<?xml version="1.0" encoding="utf-8" ?>
<!-- =================================================================================== -->
<!-- |    This document was autogenerated by xacro from /home/axalta/axalta_ws/src/axalta_mir_robot_ur10e_with_realsense/urdf/axalta_mir_model_ur10_with_rscam.xacro | -->
<!-- |    EDITING THIS FILE BY HAND IS NOT RECOMMENDED                                 | -->
<!-- =================================================================================== -->
<robot name="axalta_robot_model_ur10e_with_rscam">
    <material name="aluminum">
        <color rgba="0.5 0.5 0.5 1" />
    </material>
    <material name="plastic">
        <color rgba="0.1 0.1 0.1 1" />
    </material>
    <!-- camera body, with origin at bottom screw mount -->
    <joint name="camera_joint" type="fixed">
        <origin rpy="0 0 0" xyz="0 0 0" />
        <parent link="camera_mount_link" />
        <child link="camera_bottom_screw_frame" />
    </joint>
    <link name="camera_bottom_screw_frame" />
    <joint name="camera_link_joint" type="fixed">
        <origin rpy="0 0 0" xyz="0.0106 0.0175 0.0125" />
        <parent link="camera_bottom_screw_frame" />
        <child link="camera_link" />
    </joint>
    <link name="camera_link">
        <visual>
            <!-- the mesh origin is at front plate in between the two infrared camera axes -->
            <origin rpy="1.57079632679 0 1.57079632679" xyz="0.0043 -0.0175 0" />
            <geometry>
                <mesh filename="package://realsense2_description/meshes/d435.dae" />
            </geometry>
        </visual>
        <collision>
            <origin rpy="0 0 0" xyz="0 -0.0175 0" />
            <geometry>
                <box size="0.02505 0.09 0.025" />
            </geometry>
        </collision>
        
<inertial>
            <!-- The following are not reliable values, and should not be used for modeling -->
            <mass value="0.072" />
            <origin xyz="0 0 0" />
            <inertia ixx="0.003881243" ixy="0.0" ixz="0.0" iyy="0.000498940" iyz="0.0" izz="0.003879257" />
        </inertial>

    </link>
    <!--
    Base UR robot series xacro macro.

    NOTE: this is NOT a URDF. It cannot directly be loaded by consumers
    expecting a flattened '.urdf' file. See the top-level '.xacro' for that
    (but note: that .xacro must still be processed by the xacro command).

    For use in '.launch' files: use one of the 'load_urX.launch' convenience
    launch files.

    This file models the base kinematic chain of a UR robot, which then gets
    parameterised by various configuration files to convert it into a UR3(e),
    UR5(e), UR10(e) or UR16e.

    NOTE: the default kinematic parameters (ie: link lengths, frame locations,
    offets, etc) do not correspond to any particular robot. They are defaults
    only. There WILL be non-zero offsets between the Forward Kinematics results
    in TF (ie: robot_state_publisher) and the values reported by the Teach
    Pendant.

    For accurate (and robot-specific) transforms, the 'kinematics_parameters_file'
    parameter MUST point to a .yaml file containing the appropriate values for
    the targetted robot.

    If using the UniversalRobots/Universal_Robots_ROS_Driver, follow the steps
    described in the readme of that repository to extract the kinematic
    calibration from the controller and generate the required .yaml file.

    Main author of the migration to yaml configs: Ludovic Delval.

    Contributors to previous versions (in no particular order):

     - Felix Messmer
     - Kelsey Hawkins
     - Wim Meeussen
     - Shaun Edwards
     - Nadia Hammoudeh Garcia
     - Dave Hershberger
     - G. vd. Hoorn
     - Philip Long
     - Dave Coleman
     - Miguel Prada
     - Mathias Luedtke
     - Marcel Schnirring
     - Felix von Drigalski
     - Felix Exner
     - Jimmy Da Silva
     - Ajit Krisshna N L
     - Muhammad Asif Rana
  -->
    <!--
    NOTE: the macro defined in this file is NOT part of the public API of this
          package. Users CANNOT rely on this file being available, or stored in
          this location. Nor can they rely on the existence of the macro.
  -->
    <transmission name="shoulder_pan_trans">
        <type>transmission_interface/SimpleTransmission</type>
        <joint name="shoulder_pan_joint">
            <hardwareInterface>hardware_interface/PositionJointInterface</hardwareInterface>
        </joint>
        <actuator name="shoulder_pan_motor">
            <mechanicalReduction>1</mechanicalReduction>
        </actuator>
    </transmission>
    <transmission name="shoulder_lift_trans">
        <type>transmission_interface/SimpleTransmission</type>
        <joint name="shoulder_lift_joint">
            <hardwareInterface>hardware_interface/PositionJointInterface</hardwareInterface>
        </joint>
        <actuator name="shoulder_lift_motor">
            <mechanicalReduction>1</mechanicalReduction>
        </actuator>
    </transmission>
    <transmission name="elbow_trans">
        <type>transmission_interface/SimpleTransmission</type>
        <joint name="elbow_joint">
            <hardwareInterface>hardware_interface/PositionJointInterface</hardwareInterface>
        </joint>
        <actuator name="elbow_motor">
            <mechanicalReduction>1</mechanicalReduction>
        </actuator>
    </transmission>
    <transmission name="wrist_1_trans">
        <type>transmission_interface/SimpleTransmission</type>
        <joint name="wrist_1_joint">
            <hardwareInterface>hardware_interface/PositionJointInterface</hardwareInterface>
        </joint>
        <actuator name="wrist_1_motor">
            <mechanicalReduction>1</mechanicalReduction>
        </actuator>
    </transmission>
    <transmission name="wrist_2_trans">
        <type>transmission_interface/SimpleTransmission</type>
        <joint name="wrist_2_joint">
            <hardwareInterface>hardware_interface/PositionJointInterface</hardwareInterface>
        </joint>
        <actuator name="wrist_2_motor">
            <mechanicalReduction>1</mechanicalReduction>
        </actuator>
    </transmission>
    <transmission name="wrist_3_trans">
        <type>transmission_interface/SimpleTransmission</type>
        <joint name="wrist_3_joint">
            <hardwareInterface>hardware_interface/PositionJointInterface</hardwareInterface>
        </joint>
        <actuator name="wrist_3_motor">
            <mechanicalReduction>1</mechanicalReduction>
        </actuator>
    </transmission>
    <!-- links: main serial chain -->
    <link name="base_link" />
    <link name="base_link_inertia">
        <visual>
            <origin rpy="0 0 3.14159265359" xyz="0 0 0" />
            <geometry>
                <mesh filename="package://ur_description/meshes/ur10e/visual/base.dae" />
            </geometry>
            <material name="LightGrey">
                <color rgba="0.7 0.7 0.7 1.0" />
            </material>
        </visual>
        <collision>
            <origin rpy="0 0 3.14159265359" xyz="0 0 0" />
            <geometry>
                <mesh filename="package://ur_description/meshes/ur10e/collision/base.stl" />
            </geometry>
        </collision>
        
<inertial>
            <mass value="4.0" />
            <origin rpy="0 0 0" xyz="0 0 0" />
            <inertia ixx="0.0061063308908" ixy="0.0" ixz="0.0" iyy="0.0061063308908" iyz="0.0" izz="0.01125" />
        </inertial>

    </link>
    <link name="shoulder_link">
        <visual>
            <origin rpy="0 0 3.14159265359" xyz="0 0 0" />
            <geometry>
                <mesh filename="package://ur_description/meshes/ur10e/visual/shoulder.dae" />
            </geometry>
            <material name="LightGrey">
                <color rgba="0.7 0.7 0.7 1.0" />
            </material>
        </visual>
        <collision>
            <origin rpy="0 0 3.14159265359" xyz="0 0 0" />
            <geometry>
                <mesh filename="package://ur_description/meshes/ur10e/collision/shoulder.stl" />
            </geometry>
        </collision>
        
<inertial>
            <mass value="7.778" />
            <origin rpy="0 0 0" xyz="0 0 0" />
            <inertia ixx="0.0314743125769" ixy="0.0" ixz="0.0" iyy="0.0314743125769" iyz="0.0" izz="0.021875625" />
        </inertial>

    </link>
    <link name="upper_arm_link">
        <visual>
            <origin rpy="1.57079632679 0 -1.57079632679" xyz="0 0 0.1762" />
            <geometry>
                <mesh filename="package://ur_description/meshes/ur10e/visual/upperarm.dae" />
            </geometry>
            <material name="LightGrey">
                <color rgba="0.7 0.7 0.7 1.0" />
            </material>
        </visual>
        <collision>
            <origin rpy="1.57079632679 0 -1.57079632679" xyz="0 0 0.1762" />
            <geometry>
                <mesh filename="package://ur_description/meshes/ur10e/collision/upperarm.stl" />
            </geometry>
        </collision>
        
<inertial>
            <mass value="12.93" />
            <origin rpy="0 1.57079632679 0" xyz="-0.306 0.0 0.175" />
            <inertia ixx="0.421753803798" ixy="0.0" ixz="0.0" iyy="0.421753803798" iyz="0.0" izz="0.036365625" />
        </inertial>

    </link>
    <link name="forearm_link">
        <visual>
            <origin rpy="1.57079632679 0 -1.57079632679" xyz="0 0 0.0393" />
            <geometry>
                <mesh filename="package://ur_description/meshes/ur10e/visual/forearm.dae" />
            </geometry>
            <material name="LightGrey">
                <color rgba="0.7 0.7 0.7 1.0" />
            </material>
        </visual>
        <collision>
            <origin rpy="1.57079632679 0 -1.57079632679" xyz="0 0 0.0393" />
            <geometry>
                <mesh filename="package://ur_description/meshes/ur10e/collision/forearm.stl" />
            </geometry>
        </collision>
        
<inertial>
            <mass value="3.87" />
            <origin rpy="0 1.57079632679 0" xyz="-0.285775 0.0 0.0393" />
            <inertia ixx="0.110793025489" ixy="0.0" ixz="0.0" iyy="0.110793025489" iyz="0.0" izz="0.010884375" />
        </inertial>

    </link>
    <link name="wrist_1_link">
        <visual>
            <!-- TODO: Move this to a parameter -->
            <origin rpy="1.57079632679 0 0" xyz="0 0 -0.135" />
            <geometry>
                <mesh filename="package://ur_description/meshes/ur10e/visual/wrist1.dae" />
            </geometry>
            <material name="LightGrey">
                <color rgba="0.7 0.7 0.7 1.0" />
            </material>
        </visual>
        <collision>
            <origin rpy="1.57079632679 0 0" xyz="0 0 -0.135" />
            <geometry>
                <mesh filename="package://ur_description/meshes/ur10e/collision/wrist1.stl" />
            </geometry>
        </collision>
        
<inertial>
            <mass value="1.96" />
            <origin rpy="0 0 0" xyz="0 0 0" />
            <inertia ixx="0.0051082479567" ixy="0.0" ixz="0.0" iyy="0.0051082479567" iyz="0.0" izz="0.0055125" />
        </inertial>

    </link>
    <link name="wrist_2_link">
        <visual>
            <origin rpy="0 0 0" xyz="0 0 -0.12" />
            <geometry>
                <mesh filename="package://ur_description/meshes/ur10e/visual/wrist2.dae" />
            </geometry>
            <material name="LightGrey">
                <color rgba="0.7 0.7 0.7 1.0" />
            </material>
        </visual>
        <collision>
            <origin rpy="0 0 0" xyz="0 0 -0.12" />
            <geometry>
                <mesh filename="package://ur_description/meshes/ur10e/collision/wrist2.stl" />
            </geometry>
        </collision>
        
<inertial>
            <mass value="1.96" />
            <origin rpy="0 0 0" xyz="0 0 0" />
            <inertia ixx="0.0051082479567" ixy="0.0" ixz="0.0" iyy="0.0051082479567" iyz="0.0" izz="0.0055125" />
        </inertial>

    </link>
    <link name="wrist_3_link">
        <visual>
            <origin rpy="1.57079632679 0 0" xyz="0 0 -0.1168" />
            <geometry>
                <mesh filename="package://ur_description/meshes/ur10e/visual/wrist3.dae" />
            </geometry>
            <material name="LightGrey">
                <color rgba="0.7 0.7 0.7 1.0" />
            </material>
        </visual>
        <collision>
            <origin rpy="1.57079632679 0 0" xyz="0 0 -0.1168" />
            <geometry>
                <mesh filename="package://ur_description/meshes/ur10e/collision/wrist3.stl" />
            </geometry>
        </collision>
        
<inertial>
            <mass value="0.202" />
            <origin rpy="0 0 0" xyz="0.0 0.0 -0.025" />
            <inertia ixx="0.000144345775595" ixy="0.0" ixz="0.0" iyy="0.000144345775595" iyz="0.0" izz="0.000204525" />
        </inertial>

    </link>
    <!--<link name="${prefix}ee_link">
      <visual>
        <origin rpy="0 0 1.57" xyz="0.45 0.0 0.0"/>
        <geometry>
          <mesh filename="package://ur_description/meshes/ur10e/Automatic_Spray_gun_Assy_.stl" scale="0.001 0.001 0.001"/>
        </geometry>
        <material name="silver"/>
      </visual>
      <collision>
        <origin rpy="0 0 1.57" xyz="0.45 0.0 0.0"/>
        <geometry>
          <mesh filename="package://ur_description/meshes/ur10e/Automatic_Spray_gun_Assy_.stl" scale="0.001 0.001 0.001"/>
        </geometry>
      </collision>
    </link>-->
    <!--<link name="${prefix}tool0"/>-->
    <link name="base" />
    <!-- joints: main serial chain -->
    <joint name="base_link-base_link_inertia" type="fixed">
        <parent link="base_link" />
        <child link="base_link_inertia" />
        <!-- 'base_link' is REP-103 aligned (so X+ forward), while the internal
           frames of the robot/controller have X+ pointing backwards.
           Use the joint between 'base_link' and 'base_link_inertia' (a dummy
           link/frame) to introduce the necessary rotation over Z (of pi rad).
      -->
        <origin rpy="0 0 3.14159265359" xyz="0 0 0" />
    </joint>
    <joint name="shoulder_pan_joint" type="revolute">
        <parent link="base_link_inertia" />
        <child link="shoulder_link" />
        <origin rpy="0 0 0" xyz="0 0 0.1807" />
        <axis xyz="0 0 1" />
        <limit effort="330.0" lower="-6.28318530718" upper="6.28318530718" velocity="2.09439510239" />
        <safety_controller k_position="20" k_velocity="0.0" soft_lower_limit="-6.13318530718" soft_upper_limit="6.13318530718" />
        <dynamics damping="0" friction="0" />
    </joint>
    <joint name="shoulder_lift_joint" type="revolute">
        <parent link="shoulder_link" />
        <child link="upper_arm_link" />
        <origin rpy="1.570796327 0 0" xyz="0 0 0" />
        <axis xyz="0 0 1" />
        <limit effort="330.0" lower="-6.28318530718" upper="6.28318530718" velocity="2.09439510239" />
        <safety_controller k_position="20" k_velocity="0.0" soft_lower_limit="-6.13318530718" soft_upper_limit="6.13318530718" />
        <dynamics damping="0" friction="0" />
    </joint>
    <joint name="elbow_joint" type="revolute">
        <parent link="upper_arm_link" />
        <child link="forearm_link" />
        <origin rpy="0 0 0" xyz="-0.6127 0 0" />
        <axis xyz="0 0 1" />
        <limit effort="150.0" lower="-3.14159265359" upper="3.14159265359" velocity="3.14159265359" />
        <safety_controller k_position="20" k_velocity="0.0" soft_lower_limit="-2.99159265359" soft_upper_limit="2.99159265359" />
        <dynamics damping="0" friction="0" />
    </joint>
    <joint name="wrist_1_joint" type="revolute">
        <parent link="forearm_link" />
        <child link="wrist_1_link" />
        <origin rpy="0 0 0" xyz="-0.57155 0 0.17415" />
        <axis xyz="0 0 1" />
        <limit effort="56.0" lower="-6.28318530718" upper="6.28318530718" velocity="3.14159265359" />
        <safety_controller k_position="20" k_velocity="0.0" soft_lower_limit="-6.13318530718" soft_upper_limit="6.13318530718" />
        <dynamics damping="0" friction="0" />
    </joint>
    <joint name="wrist_2_joint" type="revolute">
        <parent link="wrist_1_link" />
        <child link="wrist_2_link" />
        <origin rpy="1.570796327 0 0" xyz="0 -0.11985 -2.45816459076e-11" />
        <axis xyz="0 0 1" />
        <limit effort="56.0" lower="-6.28318530718" upper="6.28318530718" velocity="3.14159265359" />
        <safety_controller k_position="20" k_velocity="0.0" soft_lower_limit="-6.13318530718" soft_upper_limit="6.13318530718" />
        <dynamics damping="0" friction="0" />
    </joint>
    <joint name="wrist_3_joint" type="revolute">
        <parent link="wrist_2_link" />
        <child link="wrist_3_link" />
        <origin rpy="1.57079632659 3.14159265359 3.14159265359" xyz="0 0.11655 -2.39048045935e-11" />
        <axis xyz="0 0 1" />
        <limit effort="56.0" lower="-6.28318530718" upper="6.28318530718" velocity="3.14159265359" />
        <safety_controller k_position="20" k_velocity="0.0" soft_lower_limit="-6.13318530718" soft_upper_limit="6.13318530718" />
        <dynamics damping="0" friction="0" />
    </joint>
    <!-- ROS-Industrial 'base' frame: base_link to UR 'Base' Coordinates transform -->
    <joint name="base_link-base_fixed_joint" type="fixed">
        <!-- Note the rotation over Z of pi radians: as base_link is REP-103
           aligned (ie: has X+ forward, Y+ left and Z+ up), this is needed
           to correctly align 'base' with the 'Base' coordinate system of
           the UR controller.
      -->
        <origin rpy="0 0 3.14159265359" xyz="0 0 0" />
        <parent link="base_link" />
        <child link="base" />
    </joint>
    <!--<joint name="${prefix}wrist_3_link-tool0_fixed_joint" type="fixed">
      <origin xyz="0 ${wrist_3_inertia_length} 0" rpy="${pi/-2.0} 0 0"/>
      <parent link="${prefix}wrist_3_link"/>
      <child link="${prefix}tool0"/>
    </joint>-->
    <!--<joint name="${prefix}ee_fixed_joint" type="fixed">
      <parent link="${prefix}wrist_3_link" />
      <child link = "${prefix}ee_link" />
      <origin xyz="0.0 ${wrist_3_inertia_length+0.402} 0.0" rpy="0.0 0.0 ${3*(pi/2)}" />
    </joint>-->
    <material name="white">
        <color rgba="1 1 1 1" />
    </material>
    <material name="black">
        <color rgba="0 0 0 1.0" />
    </material>
    <material name="LightGrey">
        <color rgba="0.7 0.7 0.7 1.0" />
    </material>
    <link name="mir_link">
        <visual>
            <geometry>
                <mesh filename="package://mir_description/meshes/visual/MIR200_base.stl" />
            </geometry>
            <material name="LightGrey" />
        </visual>
        <collision>
            <geometry>
                <mesh filename="package://mir_description/meshes/collision/MIR200_base.stl" />
            </geometry>
            <material name="LightGrey" />
        </collision>
        
<inertial>
            <mass value="0.1" />
            <inertia ixx="0.03" iyy="0.03" izz="0.03" ixy="0.0" ixz="0.0" iyz="0.0" />
        </inertial>

    </link>
    <link name="box1">
        <visual>
            <origin rpy="4.71238898038 3.14159265359 0" xyz="0.45 -0.3 -0.185" />
            <geometry>
                <mesh filename="package://axalta_mir_robot_ur10e/meshes/Dummy_Chassis.dae" scale="0.001 0.001 0.001" />
            </geometry>
        </visual>
        <collision>
            <origin rpy="4.71238898038 3.14159265359 0" xyz="0.45 -0.3 -0.185" />
            <geometry>
                <mesh filename="package://axalta_mir_robot_ur10e/meshes/Dummy_Chassis.dae" scale="0.001 0.001 0.001" />
            </geometry>
        </collision>
        
<inertial>
            <mass value="0.1" />
            <inertia ixx="0.03" iyy="0.03" izz="0.03" ixy="0.0" ixz="0.0" iyz="0.0" />
        </inertial>

    </link>
    <link name="wall">
        <visual>
            <geometry>
                <box size="3.0 0.2 2.0" />
            </geometry>
            <material name="black" />
        </visual>
        <collision>
            <geometry>
                <box size="3.0 0.2 2.0" />
            </geometry>
            <material name="black" />
        </collision>
        
<inertial>
            <mass value="0.1" />
            <inertia ixx="0.03" iyy="0.03" izz="0.03" ixy="0.0" ixz="0.0" iyz="0.0" />
        </inertial>

    </link>
    <link name="wheel1">
        <visual>
            <geometry>
                <cylinder length="0.05" radius="0.1" />
            </geometry>
            <material name="black" />
        </visual>
        <collision>
            <geometry>
                <cylinder length="0.05" radius="0.1" />
            </geometry>
            <material name="black" />
        </collision>
        
<inertial>
            <mass value="0.1" />
            <inertia ixx="0.03" iyy="0.03" izz="0.03" ixy="0.0" ixz="0.0" iyz="0.0" />
        </inertial>

    </link>
    <link name="wheel2">
        <visual>
            <geometry>
                <cylinder length="0.05" radius="0.1" />
            </geometry>
            <material name="black" />
        </visual>
        <collision>
            <geometry>
                <cylinder length="0.05" radius="0.1" />
            </geometry>
            <material name="black" />
        </collision>
        
<inertial>
            <mass value="0.1" />
            <inertia ixx="0.03" iyy="0.03" izz="0.03" ixy="0.0" ixz="0.0" iyz="0.0" />
        </inertial>

    </link>
    <link name="wheel3">
        <visual>
            <geometry>
                <cylinder length="0.05" radius="0.1" />
            </geometry>
            <material name="black" />
        </visual>
        <collision>
            <geometry>
                <cylinder length="0.05" radius="0.1" />
            </geometry>
            <material name="black" />
        </collision>
        
<inertial>
            <mass value="0.1" />
            <inertia ixx="0.03" iyy="0.03" izz="0.03" ixy="0.0" ixz="0.0" iyz="0.0" />
        </inertial>

    </link>
    <link name="wheel4">
        <visual>
            <geometry>
                <cylinder length="0.05" radius="0.1" />
            </geometry>
            <material name="black" />
        </visual>
        <collision>
            <geometry>
                <cylinder length="0.05" radius="0.1" />
            </geometry>
            <material name="black" />
        </collision>
        
<inertial>
            <mass value="0.1" />
            <inertia ixx="0.03" iyy="0.03" izz="0.03" ixy="0.0" ixz="0.0" iyz="0.0" />
        </inertial>

    </link>
    <!--<link name="rs_camera_pos_link">
<visual>
   <geometry>
     <cylinder length="0.05" radius="0.1"/>
    </geometry>
    <material name="black"/>
</visual>
<collision>
   <geometry>
     <cylinder length="0.05" radius="0.1"/>
    </geometry>
    <material name="black"/>
</collision>
</link>-->
    <link name="camera_mount_link">
        <visual>
            <geometry>
                <cylinder length="0.04" radius="0.05" />
            </geometry>
            <material name="black" />
        </visual>
        <collision>
            <geometry>
                <cylinder length="0.04" radius="0.05" />
            </geometry>
            <material name="black" />
        </collision>
        
<inertial>
            <mass value="0.1" />
            <inertia ixx="0.03" iyy="0.03" izz="0.03" ixy="0.0" ixz="0.0" iyz="0.0" />
        </inertial>

    </link>
    <joint name="mir_box1_joint" type="fixed">
        <parent link="mir_link" />
        <child link="box1" />
        <origin rpy="0 0 3.1416" xyz="-0.04 -0.01 0.54" />
    </joint>
    <joint name="mir_wheel1_joint" type="fixed">
        <parent link="mir_link" />
        <child link="wheel1" />
        <origin rpy="-1.6 0 0" xyz="-0.3 -0.23 0.1" />
    </joint>
    <joint name="mir_wheel2_joint" type="fixed">
        <parent link="mir_link" />
        <child link="wheel2" />
        <origin rpy="-1.6 0 0" xyz="-0.3 0.23 0.1" />
    </joint>
    <joint name="mir_wheel3_joint" type="fixed">
        <parent link="mir_link" />
        <child link="wheel3" />
        <origin rpy="-1.6 0 0" xyz="0.3 -0.23 0.1" />
    </joint>
    <joint name="mir_wheel4_joint" type="fixed">
        <parent link="mir_link" />
        <child link="wheel4" />
        <origin rpy="-1.6 0 0" xyz="0.3 0.23 0.1" />
    </joint>
    <joint name="box1_ur10e_joint" type="fixed">
        <parent link="box1" />
        <child link="base_link" />
        <origin rpy="0 0 3.1416" xyz="-0.04 -0.01 0.115" />
        <pose>-0 0 0 0 0 0</pose>
    </joint>
    <joint name="wall_joint" type="fixed">
        <parent link="box1" />
        <child link="wall" />
        <origin rpy="0 0 3.1416" xyz="0 0.4507 0.45" />
        <pose>0 0 0 0 0 0</pose>
    </joint>
    <joint name="camera_mount_joint" type="fixed">
        <parent link="wrist_3_link" />
        <child link="camera_mount_link" />
        <origin rpy="0 0 0" xyz="0 0 0.0" />
        <pose>0 0 0 0 0 0</pose>
    </joint>
    <joint name="rs_camera_joint" type="fixed">
        <parent link="camera_mount_link" />
        <child link="camera_link" />
        <origin rpy="1.57 -1.57 0" xyz="-0.0175 0 0.04" />
        <pose>0 0 0 0 0 0</pose>
    </joint>
    <transmission name="trans_shoulder_pan_joint">
        <type>transmission_interface/SimpleTransmission</type>
        <joint name="shoulder_pan_joint">
            <hardwareInterface>hardware_interface/EffortJointInterface</hardwareInterface>
        </joint>
        <actuator name="shoulder_pan_joint_motor">
            <hardwareInterface>hardware_interface/EffortJointInterface</hardwareInterface>
            <mechanicalReduction>1</mechanicalReduction>
        </actuator>
    </transmission>
    <transmission name="trans_shoulder_lift_joint">
        <type>transmission_interface/SimpleTransmission</type>
        <joint name="shoulder_lift_joint">
            <hardwareInterface>hardware_interface/EffortJointInterface</hardwareInterface>
        </joint>
        <actuator name="shoulder_lift_joint_motor">
            <hardwareInterface>hardware_interface/EffortJointInterface</hardwareInterface>
            <mechanicalReduction>1</mechanicalReduction>
        </actuator>
    </transmission>
    <transmission name="trans_elbow_joint">
        <type>transmission_interface/SimpleTransmission</type>
        <joint name="elbow_joint">
            <hardwareInterface>hardware_interface/EffortJointInterface</hardwareInterface>
        </joint>
        <actuator name="elbow_joint_motor">
            <hardwareInterface>hardware_interface/EffortJointInterface</hardwareInterface>
            <mechanicalReduction>1</mechanicalReduction>
        </actuator>
    </transmission>
    <transmission name="trans_wrist_1_joint">
        <type>transmission_interface/SimpleTransmission</type>
        <joint name="wrist_1_joint">
            <hardwareInterface>hardware_interface/EffortJointInterface</hardwareInterface>
        </joint>
        <actuator name="wrist_1_joint_motor">
            <hardwareInterface>hardware_interface/EffortJointInterface</hardwareInterface>
            <mechanicalReduction>1</mechanicalReduction>
        </actuator>
    </transmission>
    <transmission name="trans_wrist_2_joint">
        <type>transmission_interface/SimpleTransmission</type>
        <joint name="wrist_2_joint">
            <hardwareInterface>hardware_interface/EffortJointInterface</hardwareInterface>
        </joint>
        <actuator name="wrist_2_joint_motor">
            <hardwareInterface>hardware_interface/EffortJointInterface</hardwareInterface>
            <mechanicalReduction>1</mechanicalReduction>
        </actuator>
    </transmission>
    <transmission name="trans_wrist_3_joint">
        <type>transmission_interface/SimpleTransmission</type>
        <joint name="wrist_3_joint">
            <hardwareInterface>hardware_interface/EffortJointInterface</hardwareInterface>
        </joint>
        <actuator name="wrist_3_joint_motor">
            <hardwareInterface>hardware_interface/EffortJointInterface</hardwareInterface>
            <mechanicalReduction>1</mechanicalReduction>
        </actuator>
    </transmission>
    <gazebo>
        <plugin name="gazebo_ros_control" filename="libgazebo_ros_control.so">
            <robotNamespace>/</robotNamespace>
        </plugin>
    </gazebo>
</robot>

<transmission name="shoulder_pan_trans">
        <type>transmission_interface/SimpleTransmission</type>
        <joint name="shoulder_pan_joint">
            <hardwareInterface>hardware_interface/PositionJointInterface</hardwareInterface>
        </joint>
        <actuator name="shoulder_pan_motor">
            <mechanicalReduction>1</mechanicalReduction>
        </actuator>
    </transmission>
    <transmission name="shoulder_lift_trans">
        <type>transmission_interface/SimpleTransmission</type>
        <joint name="shoulder_lift_joint">
            <hardwareInterface>hardware_interface/PositionJointInterface</hardwareInterface>
        </joint>
        <actuator name="shoulder_lift_motor">
            <mechanicalReduction>1</mechanicalReduction>
        </actuator>
    </transmission>
    <transmission name="elbow_trans">
        <type>transmission_interface/SimpleTransmission</type>
        <joint name="elbow_joint">
            <hardwareInterface>hardware_interface/PositionJointInterface</hardwareInterface>
        </joint>
        <actuator name="elbow_motor">
            <mechanicalReduction>1</mechanicalReduction>
        </actuator>
    </transmission>
    <transmission name="wrist_1_trans">
        <type>transmission_interface/SimpleTransmission</type>
        <joint name="wrist_1_joint">
            <hardwareInterface>hardware_interface/PositionJointInterface</hardwareInterface>
        </joint>
        <actuator name="wrist_1_motor">
            <mechanicalReduction>1</mechanicalReduction>
        </actuator>
    </transmission>
    <transmission name="wrist_2_trans">
        <type>transmission_interface/SimpleTransmission</type>
        <joint name="wrist_2_joint">
            <hardwareInterface>hardware_interface/PositionJointInterface</hardwareInterface>
        </joint>
        <actuator name="wrist_2_motor">
            <mechanicalReduction>1</mechanicalReduction>
        </actuator>
    </transmission>
    <transmission name="wrist_3_trans">
        <type>transmission_interface/SimpleTransmission</type>
        <joint name="wrist_3_joint">
            <hardwareInterface>hardware_interface/PositionJointInterface</hardwareInterface>
        </joint>
        <actuator name="wrist_3_motor">
            <mechanicalReduction>1</mechanicalReduction>
        </actuator>
    </transmission>
    <!-- links: main serial chain -->
    <link name="base_link" />
    <link name="base_link_inertia">
        <visual>
            <origin rpy="0 0 3.14159265359" xyz="0 0 0" />
            <geometry>
                <mesh filename="package://ur_description/meshes/ur10e/visual/base.dae" />
            </geometry>
            <material name="LightGrey">
                <color rgba="0.7 0.7 0.7 1.0" />
            </material>
        </visual>
        <collision>
            <origin rpy="0 0 3.14159265359" xyz="0 0 0" />
            <geometry>
                <mesh filename="package://ur_description/meshes/ur10e/collision/base.stl" />
            </geometry>
        </collision>
        <inertial>
            <mass value="4.0" />
            <origin rpy="0 0 0" xyz="0 0 0" />
            <inertia ixx="0.0061063308908" ixy="0.0" ixz="0.0" iyy="0.0061063308908" iyz="0.0" izz="0.01125" />
        </inertial>
    </link>
    <link name="shoulder_link">
        <visual>
            <origin rpy="0 0 3.14159265359" xyz="0 0 0" />
            <geometry>
                <mesh filename="package://ur_description/meshes/ur10e/visual/shoulder.dae" />
            </geometry>
            <material name="LightGrey">
                <color rgba="0.7 0.7 0.7 1.0" />
            </material>
        </visual>
        <collision>
            <origin rpy="0 0 3.14159265359" xyz="0 0 0" />
            <geometry>
                <mesh filename="package://ur_description/meshes/ur10e/collision/shoulder.stl" />
            </geometry>
        </collision>
        <inertial>
            <mass value="7.778" />
            <origin rpy="0 0 0" xyz="0 0 0" />
            <inertia ixx="0.0314743125769" ixy="0.0" ixz="0.0" iyy="0.0314743125769" iyz="0.0" izz="0.021875625" />
        </inertial>
    </link>
    <link name="upper_arm_link">
        <visual>
            <origin rpy="1.57079632679 0 -1.57079632679" xyz="0 0 0.1762" />
            <geometry>
                <mesh filename="package://ur_description/meshes/ur10e/visual/upperarm.dae" />
            </geometry>
            <material name="LightGrey">
                <color rgba="0.7 0.7 0.7 1.0" />
            </material>
        </visual>
        <collision>
            <origin rpy="1.57079632679 0 -1.57079632679" xyz="0 0 0.1762" />
            <geometry>
                <mesh filename="package://ur_description/meshes/ur10e/collision/upperarm.stl" />
            </geometry>
        </collision>
        <inertial>
            <mass value="12.93" />
            <origin rpy="0 1.57079632679 0" xyz="-0.306 0.0 0.175" />
            <inertia ixx="0.421753803798" ixy="0.0" ixz="0.0" iyy="0.421753803798" iyz="0.0" izz="0.036365625" />
        </inertial>
    </link>
    <link name="forearm_link">
        <visual>
            <origin rpy="1.57079632679 0 -1.57079632679" xyz="0 0 0.0393" />
            <geometry>
                <mesh filename="package://ur_description/meshes/ur10e/visual/forearm.dae" />
            </geometry>
            <material name="LightGrey">
                <color rgba="0.7 0.7 0.7 1.0" />
            </material>
        </visual>
        <collision>
            <origin rpy="1.57079632679 0 -1.57079632679" xyz="0 0 0.0393" />
            <geometry>
                <mesh filename="package://ur_description/meshes/ur10e/collision/forearm.stl" />
            </geometry>
        </collision>
        <inertial>
            <mass value="3.87" />
            <origin rpy="0 1.57079632679 0" xyz="-0.285775 0.0 0.0393" />
            <inertia ixx="0.110793025489" ixy="0.0" ixz="0.0" iyy="0.110793025489" iyz="0.0" izz="0.010884375" />
        </inertial>
    </link>
    <link name="wrist_1_link">
        <visual>
            <!-- TODO: Move this to a parameter -->
            <origin rpy="1.57079632679 0 0" xyz="0 0 -0.135" />
            <geometry>
                <mesh filename="package://ur_description/meshes/ur10e/visual/wrist1.dae" />
            </geometry>
            <material name="LightGrey">
                <color rgba="0.7 0.7 0.7 1.0" />
            </material>
        </visual>
        <collision>
            <origin rpy="1.57079632679 0 0" xyz="0 0 -0.135" />
            <geometry>
                <mesh filename="package://ur_description/meshes/ur10e/collision/wrist1.stl" />
            </geometry>
        </collision>
        <inertial>
            <mass value="1.96" />
            <origin rpy="0 0 0" xyz="0 0 0" />
            <inertia ixx="0.0051082479567" ixy="0.0" ixz="0.0" iyy="0.0051082479567" iyz="0.0" izz="0.0055125" />
        </inertial>
    </link>
    <link name="wrist_2_link">
        <visual>
            <origin rpy="0 0 0" xyz="0 0 -0.12" />
            <geometry>
                <mesh filename="package://ur_description/meshes/ur10e/visual/wrist2.dae" />
            </geometry>
            <material name="LightGrey">
                <color rgba="0.7 0.7 0.7 1.0" />
            </material>
        </visual>
        <collision>
            <origin rpy="0 0 0" xyz="0 0 -0.12" />
            <geometry>
                <mesh filename="package://ur_description/meshes/ur10e/collision/wrist2.stl" />
            </geometry>
        </collision>
        <inertial>
            <mass value="1.96" />
            <origin rpy="0 0 0" xyz="0 0 0" />
            <inertia ixx="0.0051082479567" ixy="0.0" ixz="0.0" iyy="0.0051082479567" iyz="0.0" izz="0.0055125" />
        </inertial>
    </link>
    <link name="wrist_3_link">
        <visual>
            <origin rpy="1.57079632679 0 0" xyz="0 0 -0.1168" />
            <geometry>
                <mesh filename="package://ur_description/meshes/ur10e/visual/wrist3.dae" />
            </geometry>
            <material name="LightGrey">
                <color rgba="0.7 0.7 0.7 1.0" />
            </material>
        </visual>
        <collision>
            <origin rpy="1.57079632679 0 0" xyz="0 0 -0.1168" />
            <geometry>
                <mesh filename="package://ur_description/meshes/ur10e/collision/wrist3.stl" />
            </geometry>
        </collision>
        <inertial>
            <mass value="0.202" />
            <origin rpy="0 0 0" xyz="0.0 0.0 -0.025" />
            <inertia ixx="0.000144345775595" ixy="0.0" ixz="0.0" iyy="0.000144345775595" iyz="0.0" izz="0.000204525" />
        </inertial>
    </link>
    <!--<link name="${prefix}ee_link">
      <visual>
        <origin rpy="0 0 1.57" xyz="0.45 0.0 0.0"/>
        <geometry>
          <mesh filename="package://ur_description/meshes/ur10e/Automatic_Spray_gun_Assy_.stl" scale="0.001 0.001 0.001"/>
        </geometry>
        <material name="silver"/>
      </visual>
      <collision>
        <origin rpy="0 0 1.57" xyz="0.45 0.0 0.0"/>
        <geometry>
          <mesh filename="package://ur_description/meshes/ur10e/Automatic_Spray_gun_Assy_.stl" scale="0.001 0.001 0.001"/>
        </geometry>
      </collision>
    </link>-->
    <!--<link name="${prefix}tool0"/>-->
    <link name="base" />
    <!-- joints: main serial chain -->
    <joint name="base_link-base_link_inertia" type="fixed">
        <parent link="base_link" />
        <child link="base_link_inertia" />
        <!-- 'base_link' is REP-103 aligned (so X+ forward), while the internal
           frames of the robot/controller have X+ pointing backwards.
           Use the joint between 'base_link' and 'base_link_inertia' (a dummy
           link/frame) to introduce the necessary rotation over Z (of pi rad).
      -->
        <origin rpy="0 0 3.14159265359" xyz="0 0 0" />
    </joint>
    <joint name="shoulder_pan_joint" type="revolute">
        <parent link="base_link_inertia" />
        <child link="shoulder_link" />
        <origin rpy="0 0 0" xyz="0 0 0.1807" />
        <axis xyz="0 0 1" />
        <limit effort="330.0" lower="-6.28318530718" upper="6.28318530718" velocity="2.09439510239" />
        <safety_controller k_position="20" k_velocity="0.0" soft_lower_limit="-6.13318530718" soft_upper_limit="6.13318530718" />
        <dynamics damping="0" friction="0" />
    </joint>
    <joint name="shoulder_lift_joint" type="revolute">
        <parent link="shoulder_link" />
        <child link="upper_arm_link" />
        <origin rpy="1.570796327 0 0" xyz="0 0 0" />
        <axis xyz="0 0 1" />
        <limit effort="330.0" lower="-6.28318530718" upper="6.28318530718" velocity="2.09439510239" />
        <safety_controller k_position="20" k_velocity="0.0" soft_lower_limit="-6.13318530718" soft_upper_limit="6.13318530718" />
        <dynamics damping="0" friction="0" />
    </joint>
    <joint name="elbow_joint" type="revolute">
        <parent link="upper_arm_link" />
        <child link="forearm_link" />
        <origin rpy="0 0 0" xyz="-0.6127 0 0" />
        <axis xyz="0 0 1" />
        <limit effort="150.0" lower="-3.14159265359" upper="3.14159265359" velocity="3.14159265359" />
        <safety_controller k_position="20" k_velocity="0.0" soft_lower_limit="-2.99159265359" soft_upper_limit="2.99159265359" />
        <dynamics damping="0" friction="0" />
    </joint>
    <joint name="wrist_1_joint" type="revolute">
        <parent link="forearm_link" />
        <child link="wrist_1_link" />
        <origin rpy="0 0 0" xyz="-0.57155 0 0.17415" />
        <axis xyz="0 0 1" />
        <limit effort="56.0" lower="-6.28318530718" upper="6.28318530718" velocity="3.14159265359" />
        <safety_controller k_position="20" k_velocity="0.0" soft_lower_limit="-6.13318530718" soft_upper_limit="6.13318530718" />
        <dynamics damping="0" friction="0" />
    </joint>
    <joint name="wrist_2_joint" type="revolute">
        <parent link="wrist_1_link" />
        <child link="wrist_2_link" />
        <origin rpy="1.570796327 0 0" xyz="0 -0.11985 -2.45816459076e-11" />
        <axis xyz="0 0 1" />
        <limit effort="56.0" lower="-6.28318530718" upper="6.28318530718" velocity="3.14159265359" />
        <safety_controller k_position="20" k_velocity="0.0" soft_lower_limit="-6.13318530718" soft_upper_limit="6.13318530718" />
        <dynamics damping="0" friction="0" />
    </joint>
    <joint name="wrist_3_joint" type="revolute">
        <parent link="wrist_2_link" />
        <child link="wrist_3_link" />
        <origin rpy="1.57079632659 3.14159265359 3.14159265359" xyz="0 0.11655 -2.39048045935e-11" />
        <axis xyz="0 0 1" />
        <limit effort="56.0" lower="-6.28318530718" upper="6.28318530718" velocity="3.14159265359" />
        <safety_controller k_position="20" k_velocity="0.0" soft_lower_limit="-6.13318530718" soft_upper_limit="6.13318530718" />
        <dynamics damping="0" friction="0" />
    </joint>
    <!-- ROS-Industrial 'base' frame: base_link to UR 'Base' Coordinates transform -->
    <joint name="base_link-base_fixed_joint" type="fixed">
        <!-- Note the rotation over Z of pi radians: as base_link is REP-103
           aligned (ie: has X+ forward, Y+ left and Z+ up), this is needed
           to correctly align 'base' with the 'Base' coordinate system of
           the UR controller.
      -->
        <origin rpy="0 0 3.14159265359" xyz="0 0 0" />
        <parent link="base_link" />
        <child link="base" />
    </joint>
    <!--<joint name="${prefix}wrist_3_link-tool0_fixed_joint" type="fixed">
      <origin xyz="0 ${wrist_3_inertia_length} 0" rpy="${pi/-2.0} 0 0"/>
      <parent link="${prefix}wrist_3_link"/>
      <child link="${prefix}tool0"/>
    </joint>-->
    <!--<joint name="${prefix}ee_fixed_joint" type="fixed">
      <parent link="${prefix}wrist_3_link" />
      <child link = "${prefix}ee_link" />
      <origin xyz="0.0 ${wrist_3_inertia_length+0.402} 0.0" rpy="0.0 0.0 ${3*(pi/2)}" />
    </joint>-->
    <material name="white">
        <color rgba="1 1 1 1" />
    </material>
    <material name="black">
        <color rgba="0 0 0 1.0" />
    </material>
    <material name="LightGrey">
        <color rgba="0.7 0.7 0.7 1.0" />
    </material>
    <link name="mir_link">
        <visual>
            <geometry>
                <mesh filename="package://mir_description/meshes/visual/MIR200_base.stl" />
            </geometry>
            <material name="LightGrey" />
        </visual>
        <collision>
            <geometry>
                <mesh filename="package://mir_description/meshes/collision/MIR200_base.stl" />
            </geometry>
            <material name="LightGrey" />
        </collision>
        <inertial>
            <mass value="0.1" />
            <inertia ixx="0.03" iyy="0.03" izz="0.03" ixy="0.0" ixz="0.0" iyz="0.0" />
        </inertial>
    </link>
    <link name="box1">
        <visual>
            <origin rpy="4.71238898038 3.14159265359 0" xyz="0.45 -0.3 -0.185" />
            <geometry>
                <mesh filename="package://axalta_mir_robot_ur10e/meshes/Dummy_Chassis.dae" scale="0.001 0.001 0.001" />
            </geometry>
        </visual>
        <collision>
            <origin rpy="4.71238898038 3.14159265359 0" xyz="0.45 -0.3 -0.185" />
            <geometry>
                <mesh filename="package://axalta_mir_robot_ur10e/meshes/Dummy_Chassis.dae" scale="0.001 0.001 0.001" />
            </geometry>
        </collision>
        <inertial>
            <mass value="0.1" />
            <inertia ixx="0.03" iyy="0.03" izz="0.03" ixy="0.0" ixz="0.0" iyz="0.0" />
        </inertial>
    </link>
    <link name="wall">
        <visual>
            <geometry>
                <box size="3.0 0.2 2.0" />
            </geometry>
            <material name="black" />
        </visual>
        <collision>
            <geometry>
                <box size="3.0 0.2 2.0" />
            </geometry>
            <material name="black" />
        </collision>
        <inertial>
            <mass value="0.1" />
            <inertia ixx="0.03" iyy="0.03" izz="0.03" ixy="0.0" ixz="0.0" iyz="0.0" />
        </inertial>
    </link>
    <link name="wheel1">
        <visual>
            <geometry>
                <cylinder length="0.05" radius="0.1" />
            </geometry>
            <material name="black" />
        </visual>
        <collision>
            <geometry>
                <cylinder length="0.05" radius="0.1" />
            </geometry>
            <material name="black" />
        </collision>
        <inertial>
            <mass value="0.1" />
            <inertia ixx="0.03" iyy="0.03" izz="0.03" ixy="0.0" ixz="0.0" iyz="0.0" />
        </inertial>
    </link>
    <link name="wheel2">
        <visual>
            <geometry>
                <cylinder length="0.05" radius="0.1" />
            </geometry>
            <material name="black" />
        </visual>
        <collision>
            <geometry>
                <cylinder length="0.05" radius="0.1" />
            </geometry>
            <material name="black" />
        </collision>
        <inertial>
            <mass value="0.1" />
            <inertia ixx="0.03" iyy="0.03" izz="0.03" ixy="0.0" ixz="0.0" iyz="0.0" />
        </inertial>
    </link>
    <link name="wheel3">
        <visual>
            <geometry>
                <cylinder length="0.05" radius="0.1" />
            </geometry>
            <material name="black" />
        </visual>
        <collision>
            <geometry>
                <cylinder length="0.05" radius="0.1" />
            </geometry>
            <material name="black" />
        </collision>
        <inertial>
            <mass value="0.1" />
            <inertia ixx="0.03" iyy="0.03" izz="0.03" ixy="0.0" ixz="0.0" iyz="0.0" />
        </inertial>
    </link>
    <link name="wheel4">
        <visual>
            <geometry>
                <cylinder length="0.05" radius="0.1" />
            </geometry>
            <material name="black" />
        </visual>
        <collision>
            <geometry>
                <cylinder length="0.05" radius="0.1" />
            </geometry>
            <material name="black" />
        </collision>
        <inertial>
            <mass value="0.1" />
            <inertia ixx="0.03" iyy="0.03" izz="0.03" ixy="0.0" ixz="0.0" iyz="0.0" />
        </inertial>
    </link>
    <!--<link name="rs_camera_pos_link">
<visual>
   <geometry>
     <cylinder length="0.05" radius="0.1"/>
    </geometry>
    <material name="black"/>
</visual>
<collision>
   <geometry>
     <cylinder length="0.05" radius="0.1"/>
    </geometry>
    <material name="black"/>
</collision>
</link>-->
    <link name="camera_mount_link">
        <visual>
            <geometry>
                <cylinder length="0.04" radius="0.05" />
            </geometry>
            <material name="black" />
        </visual>
        <collision>
            <geometry>
                <cylinder length="0.04" radius="0.05" />
            </geometry>
            <material name="black" />
        </collision>
        <inertial>
            <mass value="0.1" />
            <inertia ixx="0.03" iyy="0.03" izz="0.03" ixy="0.0" ixz="0.0" iyz="0.0" />
        </inertial>
    </link>
    <joint name="mir_box1_joint" type="fixed">
        <parent link="mir_link" />
        <child link="box1" />
        <origin rpy="0 0 3.1416" xyz="-0.04 -0.01 0.54" />
    </joint>
    <joint name="mir_wheel1_joint" type="fixed">
        <parent link="mir_link" />
        <child link="wheel1" />
        <origin rpy="-1.6 0 0" xyz="-0.3 -0.23 0.1" />
    </joint>
    <joint name="mir_wheel2_joint" type="fixed">
        <parent link="mir_link" />
        <child link="wheel2" />
        <origin rpy="-1.6 0 0" xyz="-0.3 0.23 0.1" />
    </joint>
    <joint name="mir_wheel3_joint" type="fixed">
        <parent link="mir_link" />
        <child link="wheel3" />
        <origin rpy="-1.6 0 0" xyz="0.3 -0.23 0.1" />
    </joint>
    <joint name="mir_wheel4_joint" type="fixed">
        <parent link="mir_link" />
        <child link="wheel4" />
        <origin rpy="-1.6 0 0" xyz="0.3 0.23 0.1" />
    </joint>
    <joint name="box1_ur10e_joint" type="fixed">
        <parent link="box1" />
        <child link="base_link" />
        <origin rpy="0 0 3.1416" xyz="-0.04 -0.01 0.115" />
        <pose>-0 0 0 0 0 0</pose>
    </joint>
    <joint name="wall_joint" type="fixed">
        <parent link="box1" />
        <child link="wall" />
        <origin rpy="0 0 3.1416" xyz="0 0.4507 0.45" />
        <pose>0 0 0 0 0 0</pose>
    </joint>
    <joint name="camera_mount_joint" type="fixed">
        <parent link="wrist_3_link" />
        <child link="camera_mount_link" />
        <origin rpy="0 0 0" xyz="0 0 0.0" />
        <pose>0 0 0 0 0 0</pose>
    </joint>
    <joint name="rs_camera_joint" type="fixed">
        <parent link="camera_mount_link" />
        <child link="camera_link" />
        <origin rpy="1.57 -1.57 0" xyz="-0.0175 0 0.04" />
        <pose>0 0 0 0 0 0</pose>
    </joint>
    <transmission name="trans_shoulder_pan_joint">
        <type>transmission_interface/SimpleTransmission</type>
        <joint name="shoulder_pan_joint">
            <hardwareInterface>hardware_interface/EffortJointInterface</hardwareInterface>
        </joint>
        <actuator name="shoulder_pan_joint_motor">
            <hardwareInterface>hardware_interface/EffortJointInterface</hardwareInterface>
            <mechanicalReduction>1</mechanicalReduction>
        </actuator>
    </transmission>
    <transmission name="trans_shoulder_lift_joint">
        <type>transmission_interface/SimpleTransmission</type>
        <joint name="shoulder_lift_joint">
            <hardwareInterface>hardware_interface/EffortJointInterface</hardwareInterface>
        </joint>
        <actuator name="shoulder_lift_joint_motor">
            <hardwareInterface>hardware_interface/EffortJointInterface</hardwareInterface>
            <mechanicalReduction>1</mechanicalReduction>
        </actuator>
    </transmission>
    <transmission name="trans_elbow_joint">
        <type>transmission_interface/SimpleTransmission</type>
        <joint name="elbow_joint">
            <hardwareInterface>hardware_interface/EffortJointInterface</hardwareInterface>
        </joint>
        <actuator name="elbow_joint_motor">
            <hardwareInterface>hardware_interface/EffortJointInterface</hardwareInterface>
            <mechanicalReduction>1</mechanicalReduction>
        </actuator>
    </transmission>
    <transmission name="trans_wrist_1_joint">
        <type>transmission_interface/SimpleTransmission</type>
        <joint name="wrist_1_joint">
            <hardwareInterface>hardware_interface/EffortJointInterface</hardwareInterface>
        </joint>
        <actuator name="wrist_1_joint_motor">
            <hardwareInterface>hardware_interface/EffortJointInterface</hardwareInterface>
            <mechanicalReduction>1</mechanicalReduction>
        </actuator>
    </transmission>
    <transmission name="trans_wrist_2_joint">
        <type>transmission_interface/SimpleTransmission</type>
        <joint name="wrist_2_joint">
            <hardwareInterface>hardware_interface/EffortJointInterface</hardwareInterface>
        </joint>
        <actuator name="wrist_2_joint_motor">
            <hardwareInterface>hardware_interface/EffortJointInterface</hardwareInterface>
            <mechanicalReduction>1</mechanicalReduction>
        </actuator>
    </transmission>
    <transmission name="trans_wrist_3_joint">
        <type>transmission_interface/SimpleTransmission</type>
        <joint name="wrist_3_joint">
            <hardwareInterface>hardware_interface/EffortJointInterface</hardwareInterface>
        </joint>
        <actuator name="wrist_3_joint_motor">
            <hardwareInterface>hardware_interface/EffortJointInterface</hardwareInterface>
            <mechanicalReduction>1</mechanicalReduction>
        </actuator>
    </transmission>
    <gazebo>
        <plugin name="gazebo_ros_control" filename="libgazebo_ros_control.so">
            <robotNamespace>/</robotNamespace>
        </plugin>
    </gazebo>
</robot>
